Workbook

Sheet Assumption
B5: x | C5: Assumption | D5: For the Year Ended (FYE)
D6: 2021 | E6: =D6+1 -> 2022 | F6: =E6+1 -> 2023 | G6: =F6+1 -> 2024 | H6: =G6+1 -> 2025 | I6: =H6+1 -> 2026 | J6: =I6+1 -> 2027 | K6: =J6+1 -> 2028
C8: Tax Rate | G8: 0.21 | H8: 0.21 | I8: 0.21 | J8: 0.21 | K8: 0.21
C10: Intangible Assets
B11: + | C11: Additions | G11: 0 | H11: 0 | I11: 0 | J11: 0 | K11: 0
C13: Amortization | D13: 512 | E13: 604 | F13: 706 | G13: 715 | H13: 631 | I13: 563 | J13: 552 | K13: 534
C15: Depreciation
C16: % of PP&E | E16: ='D&A Schedule'!E16/SUM('D&A Schedule'!E9:E10) -> 0.18451185 | F16: ='D&A Schedule'!F16/SUM('D&A Schedule'!F9:F10) -> 0.20028483 | G16: =AVERAGE(E16:F16) -> 0.19239834 | H16: =G16 -> 0.19239834 | I16: =H16 -> 0.19239834 | J16: =I16 -> 0.19239834 | K16: =J16 -> 0.19239834
C19: Working Capital
C20: DSO | E20: ='Working Cap Schedule'!E36/'Working Cap Schedule'!E25 -> 26.630258 | F20: ='Working Cap Schedule'!F36/'Working Cap Schedule'!F25 -> 30.040576 | G20: =AVERAGE(E20:F20) -> 28.335417 | H20: =G20 -> 28.335417 | I20: =H20 -> 28.335417 | J20: =I20 -> 28.335417 | K20: =J20 -> 28.335417
C21: DIH | E21: ='Working Cap Schedule'!E36/'Working Cap Schedule'!E26 -> 42.521474 | F21: ='Working Cap Schedule'!F36/'Working Cap Schedule'!F26 -> 40.557485 | G21: =AVERAGE(E21:F21) -> 41.53948 | H21: =G21 -> 41.53948 | I21: =H21 -> 41.53948 | J21: =I21 -> 41.53948 | K21: =J21 -> 41.53948
C23: DPO | E23: ='Working Cap Schedule'!E36/'Working Cap Schedule'!E28 -> 100.00028 | F23: ='Working Cap Schedule'!F36/'Working Cap Schedule'!F28 -> 98.563139 | G23: =AVERAGE(E23:F23) -> 99.281708 | H23: =G23 -> 99.281708 | I23: =H23 -> 99.281708 | J23: =I23 -> 99.281708 | K23: =J23 -> 99.281708
C26: Debt and interest schedule
B27: + | C27: Issuance | G27: 0 | H27: 0 | I27: 0 | J27: 0 | K27: 0
B28: - | C28: Repurchase | G28: -8500 | H28: -5286 | I28: -3146 | J28: -8750 | K28: -2250
C30: Interest on Income | G30: 0.005
C31: Interest on expense | G31: 0.021526599
C33: Equity schedule
B34: + | C34: Issuance | G34: 0 | H34: 0 | I34: 0 | J34: 0 | K34: 0
B35: - | C35: Repurchase | G35: 0 | H35: 0 | I35: 0 | J35: 0 | K35: 0
C39: share outstatnding | E39: =10387381291/1000000 -> 10387.381

Sheet Scenerio
B2: x | D2: For the Year Ended (FYE)
D3: 2021 | E3: =D3+1 -> 2022 | F3: =E3+1 -> 2023 | G3: =F3+1 -> 2024 | H3: =G3+1 -> 2025 | I3: =H3+1 -> 2026 | J3: =I3+1 -> 2027 | K3: =J3+1 -> 2028
C5: Online stores | E5: 1 | G5: =CHOOSE($E$5,G6,G7,G8) -> 0.03 | H5: =CHOOSE($E$5,H6,H7,H8) -> 0.03 | I5: =CHOOSE($E$5,I6,I7,I8) -> 0.03 | J5: =CHOOSE($E$5,J6,J7,J8) -> 0.03 | K5: =CHOOSE($E$5,K6,K7,K8) -> 0.03
C6: Base Case | G6: 0.03 | H6: 0.03 | I6: 0.03 | J6: 0.03 | K6: 0.03
C7: Best Case | G7: 0.04 | H7: 0.04 | I7: 0.04 | J7: 0.04 | K7: 0.04
C8: Worst Case | G8: 0.02 | H8: 0.02 | I8: 0.02 | J8: 0.02 | K8: 0.02
C10: Physical stores | G10: =CHOOSE($E$5,G11,G12,G13) -> 0.05 | H10: =CHOOSE($E$5,H11,H12,H13) -> 0.06 | I10: =CHOOSE($E$5,I11,I12,I13) -> 0.06 | J10: =CHOOSE($E$5,J11,J12,J13) -> 0.06 | K10: =CHOOSE($E$5,K11,K12,K13) -> 0.06
C11: Base Case | G11: 0.05 | H11: 0.06 | I11: 0.06 | J11: 0.06 | K11: 0.06
C12: Best Case | G12: 0.06 | H12: 0.06 | I12: 0.06 | J12: 0.06 | K12: 0.06
C13: Worst Case | G13: 0.04 | H13: 0.04 | I13: 0.04 | J13: 0.04 | K13: 0.04
C15: Third party stores | G15: =CHOOSE($E$5,G16,G17,G18) -> 0.15 | H15: =CHOOSE($E$5,H16,H17,H18) -> 0.15 | I15: =CHOOSE($E$5,I16,I17,I18) -> 0.15 | J15: =CHOOSE($E$5,J16,J17,J18) -> 0.15 | K15: =CHOOSE($E$5,K16,K17,K18) -> 0.15
C16: Base Case | G16: 0.15 | H16: 0.15 | I16: 0.15 | J16: 0.15 | K16: 0.15
C17: Best Case | G17: 0.16 | H17: 0.16 | I17: 0.16 | J17: 0.16 | K17: 0.16
C18: Worst Case | G18: 0.14 | H18: 0.14 | I18: 0.14 | J18: 0.14 | K18: 0.14
C20: Advertisement stores | G20: =CHOOSE($E$5,G21,G22,G23) -> 0.215 | H20: =CHOOSE($E$5,H21,H22,H23) -> 0.215 | I20: =CHOOSE($E$5,I21,I22,I23) -> 0.215 | J20: =CHOOSE($E$5,J21,J22,J23) -> 0.215 | K20: =CHOOSE($E$5,K21,K22,K23) -> 0.215
C21: Base Case | G21: 0.215 | H21: 0.215 | I21: 0.215 | J21: 0.215 | K21: 0.215
C22: Best Case | G22: 0.225 | H22: 0.225 | I22: 0.225 | J22: 0.225 | K22: 0.225
C23: Worst Case | G23: 0.205 | H23: 0.205 | I23: 0.205 | J23: 0.205 | K23: 0.205
C25: Subscription stores | G25: =CHOOSE($E$5,G26,G27,G28) -> 0.115 | H25: =CHOOSE($E$5,H26,H27,H28) -> 0.115 | I25: =CHOOSE($E$5,I26,I27,I28) -> 0.115 | J25: =CHOOSE($E$5,J26,J27,J28) -> 0.115 | K25: =CHOOSE($E$5,K26,K27,K28) -> 0.115
C26: Base Case | G26: 0.115 | H26: 0.115 | I26: 0.115 | J26: 0.115 | K26: 0.115
C27: Best Case | G27: 0.125 | H27: 0.125 | I27: 0.125 | J27: 0.125 | K27: 0.125
C28: Worst Case | G28: 0.105 | H28: 0.105 | I28: 0.105 | J28: 0.105 | K28: 0.105
C30: AWS | G30: =CHOOSE($E$5,G31,G32,G33) -> 0.17 | H30: =CHOOSE($E$5,H31,H32,H33) -> 0.17 | I30: =CHOOSE($E$5,I31,I32,I33) -> 0.17 | J30: =CHOOSE($E$5,J31,J32,J33) -> 0.17 | K30: =CHOOSE($E$5,K31,K32,K33) -> 0.17
C31: Base Case | G31: 0.17 | H31: 0.17 | I31: 0.17 | J31: 0.17 | K31: 0.17
C32: Best Case | G32: 0.18 | H32: 0.18 | I32: 0.18 | J32: 0.18 | K32: 0.18
C33: Worst Case | G33: 0.16 | H33: 0.16 | I33: 0.16 | J33: 0.16 | K33: 0.16
C35: Others | G35: =CHOOSE($E$5,G36,G37,G38) -> 0.14 | H35: =CHOOSE($E$5,H36,H37,H38) -> 0.14 | I35: =CHOOSE($E$5,I36,I37,I38) -> 0.14 | J35: =CHOOSE($E$5,J36,J37,J38) -> 0.14 | K35: =CHOOSE($E$5,K36,K37,K38) -> 0.14
C36: Base Case | G36: 0.14 | H36: 0.14 | I36: 0.14 | J36: 0.14 | K36: 0.14
C37: Best Case | G37: 0.15 | H37: 0.15 | I37: 0.15 | J37: 0.15 | K37: 0.15
C38: Worst Case | G38: 0.13 | H38: 0.13 | I38: 0.13 | J38: 0.13 | K38: 0.13

Sheet Revenue model
A4: x | B4: Revenue Model
F5: Q1 2021 | G5: Q2 2021 | H5: Q3 2021 | I5: Q4 2021 | J5: FY 2021A | K5: Q1 2022 | L5: Q2 2022 | M5: Q3 2022 | N5: Q4 2022 | O5: FY 2022A | P5: Q1 2023 | Q5: Q2 2023 | R5: Q3 2023 | S5: Q4 2023 | T5: FY 2023A | U5: FY2024E | V5: FY2025E | W5: 2026 | X5: 2027 | Y5: 2028
B7: Segements
B8: Online stores | F8: 52901 | G8: 53157 | H8: 49942 | I8: 66075 | J8: =SUM(F8:I8) -> 222075 | K8: 51129 | L8: 50855 | M8: 53489 | N8: 64531 | O8: =SUM(K8:N8) -> 220004 | P8: 51096 | Q8: 52966 | R8: 57267 | S8: 70543 | T8: =SUM(P8:S8) -> 231872 | U8: =T8*(1+U9) -> 238828.16 | V8: =U8*(1+V9) -> 245993 | W8: =V8*(1+W9) -> 253372.79 | X8: =W8*(1+X9) -> 260973.98 | Y8: =X8*(1+Y9) -> 268803.2
B9: YOY% | O9: =O8/J8-1 -> -0.0093256783 | T9: =T8/O8-1 -> 0.053944474 | U9: =Scenerio!G5 -> 0.03 | V9: =Scenerio!H5 -> 0.03 | W9: =Scenerio!I5 -> 0.03 | X9: =Scenerio!J5 -> 0.03 | Y9: =Scenerio!K5 -> 0.03
B10: physical stores | F10: 3920 | G10: 4198 | H10: 4269 | I10: 4688 | J10: =SUM(F10:I10) -> 17075 | K10: 4591 | L10: 4721 | M10: 4694 | N10: 4957 | O10: =SUM(K10:N10) -> 18963 | P10: 4895 | Q10: 5024 | R10: 4959 | S10: 5152 | T10: =SUM(P10:S10) -> 20030 | U10: =T10*(1+U11) -> 21031.5 | V10: =U10*(1+V11) -> 22293.39 | W10: =V10*(1+W11) -> 23630.993 | X10: =W10*(1+X11) -> 25048.853 | Y10: =X10*(1+Y11) -> 26551.784
B11: YOY% | O11: =O10/J10-1 -> 0.11057101 | T11: =T10/O10-1 -> 0.056267468 | U11: =Scenerio!G10 -> 0.05 | V11: =Scenerio!H10 -> 0.06 | W11: =Scenerio!I10 -> 0.06 | X11: =Scenerio!J10 -> 0.06 | Y11: =Scenerio!K10 -> 0.06
B12: Third party stores | F12: 23709 | G12: 25085 | H12: 24252 | I12: 30320 | J12: =SUM(F12:I12) -> 103366 | K12: 25335 | L12: 27376 | M12: 28666 | N12: 36339 | O12: =SUM(K12:N12) -> 117716 | P12: 29820 | Q12: 32332 | R12: 34342 | S12: 43559 | T12: =SUM(P12:S12) -> 140053 | U12: =T12*(1+U13) -> 161060.95 | V12: =U12*(1+V13) -> 185220.09 | W12: =V12*(1+W13) -> 213003.11 | X12: =W12*(1+X13) -> 244953.57 | Y12: =X12*(1+Y13) -> 281696.61
B13: YOY% | O13: =O12/J12-1 -> 0.13882708 | T13: =T12/O12-1 -> 0.1897533 | U13: =Scenerio!G15 -> 0.15 | V13: =Scenerio!H15 -> 0.15 | W13: =Scenerio!I15 -> 0.15 | X13: =Scenerio!J15 -> 0.15 | Y13: =Scenerio!K15 -> 0.15
B14: advertisement stores | F14: 6381 | G14: 7451 | H14: 7612 | I14: 9716 | J14: =SUM(F14:I14) -> 31160 | K14: 7877 | L14: 8757 | M14: 9548 | N14: 11557 | O14: =SUM(K14:N14) -> 37739 | P14: 9509 | Q14: 10683 | R14: 12060 | S14: 14654 | T14: =SUM(P14:S14) -> 46906 | U14: =T14*(1+U15) -> 56990.79 | V14: =U14*(1+V15) -> 69243.81 | W14: =V14*(1+W15) -> 84131.229 | X14: =W14*(1+X15) -> 102219.44 | Y14: =X14*(1+Y15) -> 124196.62
B15: YOY% | O15: =O14/J14-1 -> 0.21113607 | T15: =T14/O14-1 -> 0.24290522 | U15: =Scenerio!G20 -> 0.215 | V15: =Scenerio!H20 -> 0.215 | W15: =Scenerio!I20 -> 0.215 | X15: =Scenerio!J20 -> 0.215 | Y15: =Scenerio!K20 -> 0.215
B16: Subscription stores | F16: 7580 | G16: 7917 | H16: 8148 | I16: 8123 | J16: =SUM(F16:I16) -> 31768 | K16: 8410 | L16: 8716 | M16: 8903 | N16: 9189 | O16: =SUM(K16:N16) -> 35218 | P16: 9657 | Q16: 9894 | R16: 10170 | S16: 10488 | T16: =SUM(P16:S16) -> 40209 | U16: =T16*(1+U17) -> 44833.035 | V16: =U16*(1+V17) -> 49988.834 | W16: =V16*(1+W17) -> 55737.55 | X16: =W16*(1+X17) -> 62147.368 | Y16: =X16*(1+Y17) -> 69294.316
B17: YOY% | O17: =O16/J16-1 -> 0.10859985 | T17: =T16/O16-1 -> 0.1417173 | U17: =Scenerio!G25 -> 0.115 | V17: =Scenerio!H25 -> 0.115 | W17: =Scenerio!I25 -> 0.115 | X17: =Scenerio!J25 -> 0.115 | Y17: =Scenerio!K25 -> 0.115
B18: AWS | F18: 13503 | G18: 14809 | H18: 16110 | I18: 17780 | J18: =SUM(F18:I18) -> 62202 | K18: 18441 | L18: 19739 | M18: 20538 | N18: 21378 | O18: =SUM(K18:N18) -> 80096 | P18: 21354 | Q18: 22140 | R18: 23059 | S18: 24204 | T18: =SUM(P18:S18) -> 90757 | U18: =T18*(1+U19) -> 106185.69 | V18: =U18*(1+V19) -> 124237.26 | W18: =V18*(1+W19) -> 145357.59 | X18: =W18*(1+X19) -> 170068.38 | Y18: =X18*(1+Y19) -> 198980.01
B19: YOY% | O19: =O18/J18-1 -> 0.28767564 | T19: =T18/O18-1 -> 0.13310278 | U19: =Scenerio!G30 -> 0.17 | V19: =Scenerio!H30 -> 0.17 | W19: =Scenerio!I30 -> 0.17 | X19: =Scenerio!J30 -> 0.17 | Y19: =Scenerio!K30 -> 0.17
B20: Others | F20: 524 | G20: 463 | H20: 479 | I20: 710 | J20: =SUM(F20:I20) -> 2176 | K20: 661 | L20: 1070 | M20: 1263 | N20: 1253 | O20: =SUM(K20:N20) -> 4247 | P20: 1027 | Q20: 1344 | R20: 1226 | S20: 1361 | T20: =SUM(P20:S20) -> 4958 | U20: =T20*(1+U21) -> 5652.12 | V20: =U20*(1+V21) -> 6443.4168 | W20: =V20*(1+W21) -> 7345.4952 | X20: =W20*(1+X21) -> 8373.8645 | Y20: =X20*(1+Y21) -> 9546.2055
B21: YOY% | O21: =O20/J20-1 -> 0.95174632 | T21: =T20/O20-1 -> 0.16741229 | U21: =Scenerio!G35 -> 0.14 | V21: =Scenerio!H35 -> 0.14 | W21: =Scenerio!I35 -> 0.14 | X21: =Scenerio!J35 -> 0.14 | Y21: =Scenerio!K35 -> 0.14
B23: Total revenue | U23: =SUM(U8,U10,U12,U14,U16,U18,U20) -> 634582.24 | V23: =SUM(V8,V10,V12,V14,V16,V18,V20) -> 703419.81 | W23: =V23*(1+W24) -> 779724.66 | X23: =W23*(1+X24) -> 864306.83 | Y23: =X23*(1+Y24) -> 958064.21
B24: YOY% | V24: =V23/U23-1 -> 0.10847697 | W24: =V24 -> 0.10847697 | X24: =W24 -> 0.10847697 | Y24: =X24 -> 0.10847697
J26: Base case | U26: 634582.24 | V26: 703419.81 | W26: 779724.66 | X26: 864306.83 | Y26: 958064.21
V27: =V26/U26-1 -> 0.10847697 | W27: =W26/V26-1 -> 0.10847697 | X27: =X26/W26-1 -> 0.10847697 | Y27: =Y26/X26-1 -> 0.10847697
J28: Best case | U28: 640330.09 | V28: 715958.61 | W28: 800519.51 | X28: 895067.79 | Y28: 1000783
V29: =V28/U28-1 -> 0.11810864 | W29: =W28/V28-1 -> 0.11810864 | X29: =X28/W28-1 -> 0.11810864 | Y29: =Y28/X28-1 -> 0.11810864
J30: Worst case | U30: 628834.4 | V30: 690575.32 | W30: 758378.17 | X30: 832838.11 | Y30: 914608.76
V31: =V30/U30-1 -> 0.09818313 | W31: =W30/V30-1 -> 0.09818313 | X31: =X30/W30-1 -> 0.09818313 | Y31: =Y30/X30-1 -> 0.09818313

Sheet Operating Model - IS, BS, CF
B3: x | C3: Income statement | D3: For the Year Ended (FYE)
D4: 2021 | E4: =D4+1 -> 2022 | F4: =E4+1 -> 2023 | G4: =F4+1 -> 2024 | H4: =G4+1 -> 2025 | I4: =H4+1 -> 2026 | J4: =I4+1 -> 2027 | K4: =J4+1 -> 2028
B5: x | C5: Revenue | D5: 469822 | E5: 513983 | F5: 574785 | G5: ='Revenue model'!U23 -> 634582.24 | H5: ='Revenue model'!V23 -> 703419.81 | I5: ='Revenue model'!W23 -> 779724.66 | J5: ='Revenue model'!X23 -> 864306.83 | K5: ='Revenue model'!Y23 -> 958064.21
C6: growth (%) | E6: =E5/D5-1 -> 0.093995173 | F6: =F5/E5-1 -> 0.11829574 | G6: =G5/F5-1 -> 0.10403411 | H6: =H5/G5-1 -> 0.10847697 | I6: =I5/H5-1 -> 0.10847697 | J6: =J5/I5-1 -> 0.10847697 | K6: =K5/J5-1 -> 0.10847697
C7: Cogs | D7: -272344 | E7: -288831 | F7: -304739 | G7: =G5*G8 -> -353631.65 | H7: =H5*H8 -> -391992.54 | I7: =I5*I8 -> -434514.71 | J7: =J5*J8 -> -481649.55 | K7: =K5*K8 -> -533897.43
C8: % of sales | D8: =D7/D5 -> -0.57967486 | E8: =E7/E5 -> -0.5619466 | F8: =F7/F5 -> -0.53017911 | G8: =AVERAGE(D8:F8) -> -0.55726686 | H8: =G8 -> -0.55726686 | I8: =H8 -> -0.55726686 | J8: =I8 -> -0.55726686 | K8: =J8 -> -0.55726686
C9: Gross Profit | D9: =SUM(D5,D7) -> 197478 | E9: =SUM(E5,E7) -> 225152 | F9: =SUM(F5,F7) -> 270046 | G9: =SUM(G5,G7) -> 280950.59 | H9: =SUM(H5,H7) -> 311427.26 | I9: =SUM(I5,I7) -> 345209.95 | J9: =SUM(J5,J7) -> 382657.28 | K9: =SUM(K5,K7) -> 424166.78
C10: SG&A
C11: Fulfillment | D11: -75111 | E11: -84299 | F11: -90619 | G11: =G5*G12 -> -101858.84 | H11: =H5*H12 -> -112908.18 | I11: =I5*I12 -> -125156.11 | J11: =J5*J12 -> -138732.67 | K11: =K5*K12 -> -153781.97
C12: % of sales | D12: =D11/D5 -> -0.15987119 | E12: =E11/E5 -> -0.16401126 | F12: =F11/F5 -> -0.15765721 | G12: =AVERAGE(D12:F12) -> -0.16051322 | H12: =G12 -> -0.16051322 | I12: =H12 -> -0.16051322 | J12: =I12 -> -0.16051322 | K12: =J12 -> -0.16051322
C13: Technology and infrastructure | D13: -56052 | E13: -73213 | F13: -85622 | G13: =G5*G14 -> -86876.581 | H13: =H5*H14 -> -96300.689 | I13: =I5*I14 -> -106747.1 | J13: =J5*J14 -> -118326.7 | K13: =K5*K14 -> -131162.42
C14: % of sales | D14: =D13/D5 -> -0.11930476 | E14: =E13/E5 -> -0.14244245 | F14: =F13/F5 -> -0.14896353 | G14: =AVERAGE(D14:F14) -> -0.13690358 | H14: =G14 -> -0.13690358 | I14: =H14 -> -0.13690358 | J14: =I14 -> -0.13690358 | K14: =J14 -> -0.13690358
C15: Marketing and sales exp | D15: -32551 | E15: -42238 | F15: -44370 | G15: =G5*G16 -> -48366.924 | H15: =H5*H16 -> -53613.622 | I15: =I5*I16 -> -59429.465 | J15: =J5*J16 -> -65876.194 | K15: =K5*K16 -> -73022.244
C16: % of sales | D16: =D15/D5 -> -0.069283686 | E16: =E15/E5 -> -0.082177815 | F16: =F15/F5 -> -0.077194081 | G16: =AVERAGE(D16:F16) -> -0.076218528 | H16: =G16 -> -0.076218528 | I16: =H16 -> -0.076218528 | J16: =I16 -> -0.076218528 | K16: =J16 -> -0.076218528
C17: General and administrative exp | D17: -8823 | E17: -11891 | F17: -11816 | G17: =G5*G18 -> -13214.48 | H17: =H5*H18 -> -14647.946 | I17: =I5*I18 -> -16236.911 | J17: =J5*J18 -> -17998.242 | K17: =K5*K18 -> -19950.637
C18: % of sales | D18: =D17/D5 -> -0.018779453 | E18: =E17/E5 -> -0.023135006 | F18: =F17/F5 -> -0.020557252 | G18: =AVERAGE(D18:F18) -> -0.020823904 | H18: =G18 -> -0.020823904 | I18: =H18 -> -0.020823904 | J18: =I18 -> -0.020823904 | K18: =J18 -> -0.020823904
C19: Other operating expense (income), net | D19: -62 | E19: -1263 | F19: -762 | G19: =G5*G20 -> -828.12088 | H19: =H5*H20 -> -917.95292 | I19: =I5*I20 -> -1017.5297 | J19: =J5*J20 -> -1127.9082 | K19: =K5*K20 -> -1250.2603
C20: % of sales | D20: =D19/D5 -> -0.00013196487 | E20: =E19/E5 -> -0.0024572797 | F20: =F19/F5 -> -0.0013257131 | G20: =AVERAGE(D20:F20) -> -0.0013049859 | H20: =G20 -> -0.0013049859 | I20: =H20 -> -0.0013049859 | J20: =I20 -> -0.0013049859 | K20: =J20 -> -0.0013049859
C21: Total Operating Exp | D21: =SUM(D11,D13,D15,D17,D19) -> -172599 | E21: =SUM(E11,E13,E15,E17,E19) -> -212904 | F21: =SUM(F11,F13,F15,F17,F19) -> -233189 | G21: =SUM(G11,G13,G15,G17,G19) -> -251144.94 | H21: =SUM(H11,H13,H15,H17,H19) -> -278388.39 | I21: =SUM(I11,I13,I15,I17,I19) -> -308587.12 | J21: =SUM(J11,J13,J15,J17,J19) -> -342061.71 | K21: =SUM(K11,K13,K15,K17,K19) -> -379167.53
C22: EBITDA | D22: =SUM(D24,D23) -> 59312 | E22: =SUM(E24,E23) -> 54169 | F22: =SUM(F24,F23) -> 85520 | G22: =SUM(G24,G23) -> 83865.494 | H22: =SUM(H24,H23) -> 92200.579 | I22: =SUM(I24,I23) -> 101611.62 | J22: =SUM(J24,J23) -> 112221.55 | K22: =SUM(K24,K23) -> 124055.99
C23: D&A | D23: 34433 | E23: 41921 | F23: 48663 | G23: ='D&A Schedule'!G14 -> 54059.846 | H23: ='D&A Schedule'!H14 -> 59161.704 | I23: ='D&A Schedule'!I14 -> 64988.791 | J23: ='D&A Schedule'!J14 -> 71625.989 | K23: ='D&A Schedule'!K14 -> 79056.745
C24: Op Income (EBIT) | D24: =SUM(D9+D21) -> 24879 | E24: =SUM(E9+E21) -> 12248 | F24: =SUM(F9+F21) -> 36857 | G24: =SUM(G9+G21) -> 29805.648 | H24: =SUM(H9+H21) -> 33038.875 | I24: =SUM(I9+I21) -> 36622.832 | J24: =SUM(J9+J21) -> 40595.566 | K24: =SUM(K9+K21) -> 44999.25
C25: Interest expense | D25: -1809 | E25: -2367 | F25: -3182 | G25: ='Debt and Interest Schedule '!G11 -> -1255.3021 | H25: ='Debt and Interest Schedule '!H11 -> -1255.3021 | I25: ='Debt and Interest Schedule '!I11 -> -1255.3021 | J25: ='Debt and Interest Schedule '!J11 -> -1255.3021 | K25: ='Debt and Interest Schedule '!K11 -> -1255.3021
C26: Interest income | D26: 448 | E26: 989 | F26: 2949 | G26: ='Debt and Interest Schedule '!G12 -> 446.81665 | H26: ='Debt and Interest Schedule '!H12 -> 519.80022 | I26: ='Debt and Interest Schedule '!I12 -> 611.97731 | J26: ='Debt and Interest Schedule '!J12 -> 685.72467 | K26: ='Debt and Interest Schedule '!K12 -> 804.95296
C27: Other income (expense), net | D27: 14633 | E27: -16806 | F27: 938 | G27: 0 | H27: 0 | I27: 0 | J27: 0 | K27: 0
C28: Profit Before Tax (PBT) | D28: =SUM(D24,D25,D26,D27) -> 38151 | E28: =SUM(E24,E25,E26,E27) -> -5936 | F28: =SUM(F24,F25,F26,F27) -> 37562 | G28: =SUM(G24,G25,G26,G27) -> 28997.163 | H28: =SUM(H24,H25,H26,H27) -> 32303.373 | I28: =SUM(I24,I25,I26,I27) -> 35979.507 | J28: =SUM(J24,J25,J26,J27) -> 40025.988 | K28: =SUM(K24,K25,K26,K27) -> 44548.901
C29: Taxes | D29: -4791 | E29: 3217 | F29: -7120 | G29: =G28*Assumption!G8 -> 6089.4042 | H29: =H28*Assumption!H8 -> 6783.7083 | I29: =I28*Assumption!I8 -> 7555.6965 | J29: =J28*Assumption!J8 -> 8405.4575 | K29: =K28*Assumption!K8 -> 9355.2691
C30: Equity-method investment activity, net of tax | D30: 4 | E30: -3 | F30: -12 | G30: 0 | H30: 0 | I30: 0 | J30: 0 | K30: 0
B31: x | C31: PAT / Net Income / Net Profit | D31: =SUM(D28,D29,D30) -> 33364 | E31: =SUM(E28,E29,E30) -> -2722 | F31: =SUM(F28,F29,F30) -> 30430 | G31: =SUM(G28,G29,G30) -> 35086.567 | H31: =SUM(H28,H29,H30) -> 39087.081 | I31: =SUM(I28,I29,I30) -> 43535.203 | J31: =SUM(J28,J29,J30) -> 48431.446 | K31: =SUM(K28,K29,K30) -> 53904.17
B34: x | C34: Balance Sheet | D34: As of
C35: Assets | D35: =D4 -> 2021 | E35: =D35+1 -> 2022 | F35: =E35+1 -> 2023 | G35: =F35+1 -> 2024 | H35: =G35+1 -> 2025 | I35: =H35+1 -> 2026 | J35: =I35+1 -> 2027 | K35: =J35+1 -> 2028
C36: Current Assets
C37: Cash and cash equivalents | D37: 36220 | E37: 53888 | F37: 73387 | G37: =G106 -> 89363.33 | H37: =H106 -> 103960.04 | I37: =I106 -> 122395.46 | J37: =J106 -> 137144.93 | K37: =K106 -> 160990.59
C38: Marketable Securities | D38: 59829 | E38: 16138 | F38: 13393 | G38: =F38 -> 13393 | H38: =G38 -> 13393 | I38: =H38 -> 13393 | J38: =I38 -> 13393 | K38: =J38 -> 13393
C39: Account Receivable | D39: 32640 | E39: 42360 | F39: 52253 | G39: ='Working Cap Schedule'!G9 -> 49263.432 | H39: ='Working Cap Schedule'!H9 -> 54607.38 | I39: ='Working Cap Schedule'!I9 -> 60531.023 | J39: ='Working Cap Schedule'!J9 -> 67097.245 | K39: ='Working Cap Schedule'!K9 -> 74375.751
C40: Inventory | D40: 32891 | E40: 34405 | F40: 33318 | G40: ='Working Cap Schedule'!G10 -> 40245.685 | H40: ='Working Cap Schedule'!H10 -> 44611.415 | I40: ='Working Cap Schedule'!I10 -> 49450.726 | J40: ='Working Cap Schedule'!J10 -> 54814.991 | K40: ='Working Cap Schedule'!K10 -> 60761.155
C41: Other CA
C42: Total Current Assets | D42: =SUM(D37:D41) -> 161580 | E42: =SUM(E37:E41) -> 146791 | F42: =SUM(F37:F41) -> 172351 | G42: =SUM(G37:G41) -> 192265.45 | H42: =SUM(H37:H41) -> 216571.84 | I42: =SUM(I37:I41) -> 245770.21 | J42: =SUM(J37:J41) -> 272450.17 | K42: =SUM(K37:K41) -> 309520.5
B44: x | C44: Non-Current Assets
C45: Prperty Plant and Equipment | D45: 160281 | E45: 186715 | F45: 204177 | G45: ='D&A Schedule'!G12 -> 223202.66 | H45: ='D&A Schedule'!H12 -> 245054.56 | I45: ='D&A Schedule'!I12 -> 269867.49 | J45: ='D&A Schedule'!J12 -> 297784.63 | K45: ='D&A Schedule'!K12 -> 329069.16
...

Sheet Ratio Analysis
B3: x | C3: Ratio Analysis | E3: For the Year Ended (FYE)
D4: Comments | E4: 2021 | F4: =E4+1 -> 2022 | G4: =F4+1 -> 2023 | H4: =G4+1 -> 2024 | I4: =H4+1 -> 2025 | J4: =I4+1 -> 2026 | K4: =J4+1 -> 2027 | L4: =K4+1 -> 2028
C6: Margin Ratios | E6: 1 | F6: 2 | G6: 3 | H6: 4 | I6: 5 | J6: 6 | K6: 7 | L6: 8
C7: Gross Margin | E7: ='Operating Model - IS, BS, CF'!D9/'Operating Model - IS, BS, CF'!D5 -> 0.42032514 | F7: ='Operating Model - IS, BS, CF'!E9/'Operating Model - IS, BS, CF'!E5 -> 0.4380534 | G7: ='Operating Model - IS, BS, CF'!F9/'Operating Model - IS, BS, CF'!F5 -> 0.46982089 | H7: ='Operating Model - IS, BS, CF'!G9/'Operating Model - IS, BS, CF'!G5 -> 0.44273314 | I7: ='Operating Model - IS, BS, CF'!H9/'Operating Model - IS, BS, CF'!H5 -> 0.44273314 | J7: ='Operating Model - IS, BS, CF'!I9/'Operating Model - IS, BS, CF'!I5 -> 0.44273314 | K7: ='Operating Model - IS, BS, CF'!J9/'Operating Model - IS, BS, CF'!J5 -> 0.44273314 | L7: ='Operating Model - IS, BS, CF'!K9/'Operating Model - IS, BS, CF'!K5 -> 0.44273314
C8: EBITDA margin | E8: ='Operating Model - IS, BS, CF'!D22/'Operating Model - IS, BS, CF'!D5 -> 0.12624356 | F8: ='Operating Model - IS, BS, CF'!E22/'Operating Model - IS, BS, CF'!E5 -> 0.10539065 | G8: ='Operating Model - IS, BS, CF'!F22/'Operating Model - IS, BS, CF'!F5 -> 0.14878607 | H8: ='Operating Model - IS, BS, CF'!G22/'Operating Model - IS, BS, CF'!G5 -> 0.13215859 | I8: ='Operating Model - IS, BS, CF'!H22/'Operating Model - IS, BS, CF'!H5 -> 0.13107476 | J8: ='Operating Model - IS, BS, CF'!I22/'Operating Model - IS, BS, CF'!I5 -> 0.13031731 | K8: ='Operating Model - IS, BS, CF'!J22/'Operating Model - IS, BS, CF'!J5 -> 0.12983995 | L8: ='Operating Model - IS, BS, CF'!K22/'Operating Model - IS, BS, CF'!K5 -> 0.1294861
C9: EBIT Margin | E9: ='Operating Model - IS, BS, CF'!D24/'Operating Model - IS, BS, CF'!D5 -> 0.052954098 | F9: ='Operating Model - IS, BS, CF'!E24/'Operating Model - IS, BS, CF'!E5 -> 0.023829582 | G9: ='Operating Model - IS, BS, CF'!F24/'Operating Model - IS, BS, CF'!F5 -> 0.064123107 | H9: ='Operating Model - IS, BS, CF'!G24/'Operating Model - IS, BS, CF'!G5 -> 0.046968929 | I9: ='Operating Model - IS, BS, CF'!H24/'Operating Model - IS, BS, CF'!H5 -> 0.046968929 | J9: ='Operating Model - IS, BS, CF'!I24/'Operating Model - IS, BS, CF'!I5 -> 0.046968929 | K9: ='Operating Model - IS, BS, CF'!J24/'Operating Model - IS, BS, CF'!J5 -> 0.046968929 | L9: ='Operating Model - IS, BS, CF'!K24/'Operating Model - IS, BS, CF'!K5 -> 0.046968929
C10: Net Income Margin | E10: ='Operating Model - IS, BS, CF'!D31/'Operating Model - IS, BS, CF'!D5 -> 0.071014129 | F10: ='Operating Model - IS, BS, CF'!E31/'Operating Model - IS, BS, CF'!E5 -> -0.005295895 | G10: ='Operating Model - IS, BS, CF'!F31/'Operating Model - IS, BS, CF'!F5 -> 0.052941535 | H10: ='Operating Model - IS, BS, CF'!G31/'Operating Model - IS, BS, CF'!G5 -> 0.055290811 | I10: ='Operating Model - IS, BS, CF'!H31/'Operating Model - IS, BS, CF'!H5 -> 0.055567217 | J10: ='Operating Model - IS, BS, CF'!I31/'Operating Model - IS, BS, CF'!I5 -> 0.055834073 | K10: ='Operating Model - IS, BS, CF'!J31/'Operating Model - IS, BS, CF'!J5 -> 0.056035015 | L10: ='Operating Model - IS, BS, CF'!K31/'Operating Model - IS, BS, CF'!K5 -> 0.056263629
C12: Profitability Ratios
C13: RoAA | F13: ='Operating Model - IS, BS, CF'!E31/AVERAGE('Operating Model - IS, BS, CF'!D52:E52) -> -0.0061637818 | G13: ='Operating Model - IS, BS, CF'!F31/AVERAGE('Operating Model - IS, BS, CF'!E52:F52) -> 0.061441916 | H13: ='Operating Model - IS, BS, CF'!G31/AVERAGE('Operating Model - IS, BS, CF'!F52:G52) -> 0.064105655 | I13: ='Operating Model - IS, BS, CF'!H31/AVERAGE('Operating Model - IS, BS, CF'!G52:H52) -> 0.066263525 | J13: ='Operating Model - IS, BS, CF'!I31/AVERAGE('Operating Model - IS, BS, CF'!H52:I52) -> 0.068028214 | K13: ='Operating Model - IS, BS, CF'!J31/AVERAGE('Operating Model - IS, BS, CF'!I52:J52) -> 0.069759584 | L13: ='Operating Model - IS, BS, CF'!K31/AVERAGE('Operating Model - IS, BS, CF'!J52:K52) -> 0.071326509
C14: RoAE | F14: =('Operating Model - IS, BS, CF'!E31/AVERAGE('Operating Model - IS, BS, CF'!D75:'Operating Model - IS, BS, CF'!E75)) -> -0.019149595 | G14: =('Operating Model - IS, BS, CF'!F31/AVERAGE('Operating Model - IS, BS, CF'!E75:'Operating Model - IS, BS, CF'!F75)) -> 0.17492628 | H14: =('Operating Model - IS, BS, CF'!G31/AVERAGE('Operating Model - IS, BS, CF'!F75:'Operating Model - IS, BS, CF'!G75)) -> 0.15990722 | I14: =('Operating Model - IS, BS, CF'!H31/AVERAGE('Operating Model - IS, BS, CF'!G75:'Operating Model - IS, BS, CF'!H75)) -> 0.15238325 | J14: =('Operating Model - IS, BS, CF'!I31/AVERAGE('Operating Model - IS, BS, CF'!H75:'Operating Model - IS, BS, CF'!I75)) -> 0.14618142 | K14: =('Operating Model - IS, BS, CF'!J31/AVERAGE('Operating Model - IS, BS, CF'!I75:'Operating Model - IS, BS, CF'!J75)) -> 0.14087116 | L14: =('Operating Model - IS, BS, CF'!K31/AVERAGE('Operating Model - IS, BS, CF'!J75:'Operating Model - IS, BS, CF'!K75)) -> 0.13647752
C15: RoCE | E15: ='Operating Model - IS, BS, CF'!E24/('Operating Model - IS, BS, CF'!D52-'Operating Model - IS, BS, CF'!D60) -> 0.04401275 | F15: ='Operating Model - IS, BS, CF'!F24/('Operating Model - IS, BS, CF'!E52-'Operating Model - IS, BS, CF'!E60) -> 0.1199452 | G15: ='Operating Model - IS, BS, CF'!G24/('Operating Model - IS, BS, CF'!F52-'Operating Model - IS, BS, CF'!F60) -> 0.082123477 | H15: ='Operating Model - IS, BS, CF'!H24/('Operating Model - IS, BS, CF'!G52-'Operating Model - IS, BS, CF'!G60) -> 0.08481868 | I15: ='Operating Model - IS, BS, CF'!I24/('Operating Model - IS, BS, CF'!H52-'Operating Model - IS, BS, CF'!H60) -> 0.086512401 | J15: ='Operating Model - IS, BS, CF'!J24/('Operating Model - IS, BS, CF'!I52-'Operating Model - IS, BS, CF'!I60) -> 0.087544432 | K15: ='Operating Model - IS, BS, CF'!K24/('Operating Model - IS, BS, CF'!J52-'Operating Model - IS, BS, CF'!J60) -> 0.089391478 | L15: ='Operating Model - IS, BS, CF'!L24/('Operating Model - IS, BS, CF'!K52-'Operating Model - IS, BS, CF'!K60) -> 0
C17: Liquidity Ratios
C18: Current Ratio | E18: ='Operating Model - IS, BS, CF'!D42/'Operating Model - IS, BS, CF'!D60 -> 1.1357598 | F18: ='Operating Model - IS, BS, CF'!E42/'Operating Model - IS, BS, CF'!E60 -> 0.94464358 | G18: ='Operating Model - IS, BS, CF'!F42/'Operating Model - IS, BS, CF'!F60 -> 1.0450772 | H18: ='Operating Model - IS, BS, CF'!G42/'Operating Model - IS, BS, CF'!G60 -> 1.0845877 | I18: ='Operating Model - IS, BS, CF'!H42/'Operating Model - IS, BS, CF'!H60 -> 1.1420894 | J18: ='Operating Model - IS, BS, CF'!I42/'Operating Model - IS, BS, CF'!I60 -> 1.2092024 | K18: ='Operating Model - IS, BS, CF'!J42/'Operating Model - IS, BS, CF'!J60 -> 1.2488233 | L18: ='Operating Model - IS, BS, CF'!K42/'Operating Model - IS, BS, CF'!K60 -> 1.3178589
C19: Quick Ratio | E19: =('Operating Model - IS, BS, CF'!D37+'Operating Model - IS, BS, CF'!D38+'Operating Model - IS, BS, CF'!D39)/'Operating Model - IS, BS, CF'!D60 -> 0.90456609 | F19: =('Operating Model - IS, BS, CF'!E37+'Operating Model - IS, BS, CF'!E38+'Operating Model - IS, BS, CF'!E39)/'Operating Model - IS, BS, CF'!E60 -> 0.72323721 | G19: =('Operating Model - IS, BS, CF'!F37+'Operating Model - IS, BS, CF'!F38+'Operating Model - IS, BS, CF'!F39)/'Operating Model - IS, BS, CF'!F60 -> 0.84304832 | H19: =('Operating Model - IS, BS, CF'!G37+'Operating Model - IS, BS, CF'!G38+'Operating Model - IS, BS, CF'!G39)/'Operating Model - IS, BS, CF'!G60 -> 0.85755794 | I19: =('Operating Model - IS, BS, CF'!H37+'Operating Model - IS, BS, CF'!H38+'Operating Model - IS, BS, CF'!H39)/'Operating Model - IS, BS, CF'!H60 -> 0.90683152 | J19: =('Operating Model - IS, BS, CF'!I37+'Operating Model - IS, BS, CF'!I38+'Operating Model - IS, BS, CF'!I39)/'Operating Model - IS, BS, CF'!I60 -> 0.96590226 | K19: =('Operating Model - IS, BS, CF'!J37+'Operating Model - IS, BS, CF'!J38+'Operating Model - IS, BS, CF'!J39)/'Operating Model - IS, BS, CF'!J60 -> 0.99756917 | L19: =('Operating Model - IS, BS, CF'!K37+'Operating Model - IS, BS, CF'!K38+'Operating Model - IS, BS, CF'!K39)/'Operating Model - IS, BS, CF'!K60 -> 1.0591535
C20: Cash Ratio | E20: =('Operating Model - IS, BS, CF'!D37+'Operating Model - IS, BS, CF'!D38)/'Operating Model - IS, BS, CF'!D60 -> 0.67513672 | F20: =('Operating Model - IS, BS, CF'!E37+'Operating Model - IS, BS, CF'!E38)/'Operating Model - IS, BS, CF'!E60 -> 0.45063806 | G20: =('Operating Model - IS, BS, CF'!F37+'Operating Model - IS, BS, CF'!F38)/'Operating Model - IS, BS, CF'!F60 -> 0.52620409 | H20: =('Operating Model - IS, BS, CF'!G37+'Operating Model - IS, BS, CF'!G38)/'Operating Model - IS, BS, CF'!G60 -> 0.57965823 | I20: =('Operating Model - IS, BS, CF'!H37+'Operating Model - IS, BS, CF'!H38)/'Operating Model - IS, BS, CF'!H60 -> 0.61886007 | J20: =('Operating Model - IS, BS, CF'!I37+'Operating Model - IS, BS, CF'!I38)/'Operating Model - IS, BS, CF'!I60 -> 0.66808642 | K20: =('Operating Model - IS, BS, CF'!J37+'Operating Model - IS, BS, CF'!J38)/'Operating Model - IS, BS, CF'!J60 -> 0.69001713 | L20: =('Operating Model - IS, BS, CF'!K37+'Operating Model - IS, BS, CF'!K38)/'Operating Model - IS, BS, CF'!K60 -> 0.74248062
C22: Leverage Ratios
C23: Debt / Equity | E23: =('Operating Model - IS, BS, CF'!D57+'Operating Model - IS, BS, CF'!D63+'Operating Model - IS, BS, CF'!D64)/'Operating Model - IS, BS, CF'!D75 -> 0.84194727 | F23: =('Operating Model - IS, BS, CF'!E57+'Operating Model - IS, BS, CF'!E63+'Operating Model - IS, BS, CF'!E64)/'Operating Model - IS, BS, CF'!E75 -> 0.95942976 | G23: =('Operating Model - IS, BS, CF'!F57+'Operating Model - IS, BS, CF'!F63+'Operating Model - IS, BS, CF'!F64)/'Operating Model - IS, BS, CF'!F75 -> 0.67175728 | H23: =('Operating Model - IS, BS, CF'!G57+'Operating Model - IS, BS, CF'!G63+'Operating Model - IS, BS, CF'!G64)/'Operating Model - IS, BS, CF'!G75 -> 0.57229112 | I23: =('Operating Model - IS, BS, CF'!H57+'Operating Model - IS, BS, CF'!H63+'Operating Model - IS, BS, CF'!H64)/'Operating Model - IS, BS, CF'!H75 -> 0.49125761 | J23: =('Operating Model - IS, BS, CF'!I57+'Operating Model - IS, BS, CF'!I63+'Operating Model - IS, BS, CF'!I64)/'Operating Model - IS, BS, CF'!I75 -> 0.42433621 | K23: =('Operating Model - IS, BS, CF'!J57+'Operating Model - IS, BS, CF'!J63+'Operating Model - IS, BS, CF'!J64)/'Operating Model - IS, BS, CF'!J75 -> 0.36849283 | L23: =('Operating Model - IS, BS, CF'!K57+'Operating Model - IS, BS, CF'!K63+'Operating Model - IS, BS, CF'!K64)/'Operating Model - IS, BS, CF'!K75 -> 0.32141442
C24: Debt / Assets | E24: =('Operating Model - IS, BS, CF'!D57+'Operating Model - IS, BS, CF'!D64+'Operating Model - IS, BS, CF'!D63)/'Operating Model - IS, BS, CF'!D52 -> 0.27676918 | F24: =('Operating Model - IS, BS, CF'!E57+'Operating Model - IS, BS, CF'!E64+'Operating Model - IS, BS, CF'!E63)/'Operating Model - IS, BS, CF'!E52 -> 0.30284325 | G24: =('Operating Model - IS, BS, CF'!F57+'Operating Model - IS, BS, CF'!F64+'Operating Model - IS, BS, CF'!F63)/'Operating Model - IS, BS, CF'!F52 -> 0.25691005 | H24: =('Operating Model - IS, BS, CF'!G57+'Operating Model - IS, BS, CF'!G64+'Operating Model - IS, BS, CF'!G63)/'Operating Model - IS, BS, CF'!G52 -> 0.23925972 | I24: =('Operating Model - IS, BS, CF'!H57+'Operating Model - IS, BS, CF'!H64+'Operating Model - IS, BS, CF'!H63)/'Operating Model - IS, BS, CF'!H52 -> 0.2212423 | J24: =('Operating Model - IS, BS, CF'!I57+'Operating Model - IS, BS, CF'!I64+'Operating Model - IS, BS, CF'!I63)/'Operating Model - IS, BS, CF'!I52 -> 0.20332591 | K24: =('Operating Model - IS, BS, CF'!J57+'Operating Model - IS, BS, CF'!J64+'Operating Model - IS, BS, CF'!J63)/'Operating Model - IS, BS, CF'!J52 -> 0.1879412 | L24: =('Operating Model - IS, BS, CF'!K57+'Operating Model - IS, BS, CF'!K64+'Operating Model - IS, BS, CF'!K63)/'Operating Model - IS, BS, CF'!K52 -> 0.17167782
C25: Debt / EBITDA | E25: =('Operating Model - IS, BS, CF'!D57+'Operating Model - IS, BS, CF'!D63+'Operating Model - IS, BS, CF'!D64)/'Operating Model - IS, BS, CF'!D22 -> 1.9624191 | F25: =('Operating Model - IS, BS, CF'!E57+'Operating Model - IS, BS, CF'!E63+'Operating Model - IS, BS, CF'!E64)/'Operating Model - IS, BS, CF'!E22 -> 2.5866824 | G25: =('Operating Model - IS, BS, CF'!F57+'Operating Model - IS, BS, CF'!F63+'Operating Model - IS, BS, CF'!F64)/'Operating Model - IS, BS, CF'!F22 -> 1.5857226 | H25: =('Operating Model - IS, BS, CF'!G57+'Operating Model - IS, BS, CF'!G63+'Operating Model - IS, BS, CF'!G64)/'Operating Model - IS, BS, CF'!G22 -> 1.6170059 | I25: =('Operating Model - IS, BS, CF'!H57+'Operating Model - IS, BS, CF'!H63+'Operating Model - IS, BS, CF'!H64)/'Operating Model - IS, BS, CF'!H22 -> 1.4708259 | J25: =('Operating Model - IS, BS, CF'!I57+'Operating Model - IS, BS, CF'!I63+'Operating Model - IS, BS, CF'!I64)/'Operating Model - IS, BS, CF'!I22 -> 1.3346013 | K25: =('Operating Model - IS, BS, CF'!J57+'Operating Model - IS, BS, CF'!J63+'Operating Model - IS, BS, CF'!J64)/'Operating Model - IS, BS, CF'!J22 -> 1.208422 | L25: =('Operating Model - IS, BS, CF'!K57+'Operating Model - IS, BS, CF'!K63+'Operating Model - IS, BS, CF'!K64)/'Operating Model - IS, BS, CF'!K22 -> 1.0931435
C27: Coverage Ratios
C28: Interest Coverage | E28: =-'Operating Model - IS, BS, CF'!D24/'Operating Model - IS, BS, CF'!D25 -> 13.752902 | F28: =-'Operating Model - IS, BS, CF'!E24/'Operating Model - IS, BS, CF'!E25 -> 5.1744825 | G28: =-'Operating Model - IS, BS, CF'!F24/'Operating Model - IS, BS, CF'!F25 -> 11.582967 | H28: =-'Operating Model - IS, BS, CF'!G24/'Operating Model - IS, BS, CF'!G25 -> 23.743805 | I28: =-'Operating Model - IS, BS, CF'!H24/'Operating Model - IS, BS, CF'!H25 -> 26.319461 | J28: =-'Operating Model - IS, BS, CF'!I24/'Operating Model - IS, BS, CF'!I25 -> 29.174516 | K28: =-'Operating Model - IS, BS, CF'!J24/'Operating Model - IS, BS, CF'!J25 -> 32.339279
C31: Conversion Ratios
C32: Approx FCFF | D32: EBITDA - Capex | E32: ='Operating Model - IS, BS, CF'!D22+('Operating Model - IS, BS, CF'!D90) -> -1741 | F32: ='Operating Model - IS, BS, CF'!E22+('Operating Model - IS, BS, CF'!E90) -> -9476 | G32: ='Operating Model - IS, BS, CF'!F22+('Operating Model - IS, BS, CF'!F90) -> 32791 | H32: ='Operating Model - IS, BS, CF'!G22+('Operating Model - IS, BS, CF'!G90) -> 10779.985 | I32: ='Operating Model - IS, BS, CF'!H22+('Operating Model - IS, BS, CF'!H90) -> 11186.975 | J32: ='Operating Model - IS, BS, CF'!I22+('Operating Model - IS, BS, CF'!I90) -> 11809.908 | K32: ='Operating Model - IS, BS, CF'!J22+('Operating Model - IS, BS, CF'!J90) -> 12678.422
C33: Conversion Ratio Multiple | D33: EBITDA - Capex / EBITDA | E33: =E32/'Operating Model - IS, BS, CF'!D22 -> -0.029353251 | F33: =F32/'Operating Model - IS, BS, CF'!E22 -> -0.174934 | G33: =G32/'Operating Model - IS, BS, CF'!F22 -> 0.38343078 | H33: =H32/'Operating Model - IS, BS, CF'!G22 -> 0.12853898 | I33: =I32/'Operating Model - IS, BS, CF'!H22 -> 0.12133302 | J33: =J32/'Operating Model - IS, BS, CF'!I22 -> 0.11622596 | K33: =K32/'Operating Model - IS, BS, CF'!J22 -> 0.11297671
C35: Turnover Ratios
C36: Receivable Turnover | F36: =('Operating Model - IS, BS, CF'!E5/AVERAGE('Operating Model - IS, BS, CF'!D39:E39)) -> 13.706213 | G36: =('Operating Model - IS, BS, CF'!F5/AVERAGE('Operating Model - IS, BS, CF'!E39:F39)) -> 12.150233 | H36: =('Operating Model - IS, BS, CF'!G5/AVERAGE('Operating Model - IS, BS, CF'!F39:G39)) -> 12.50206 | I36: =('Operating Model - IS, BS, CF'!H5/AVERAGE('Operating Model - IS, BS, CF'!G39:H39)) -> 13.544128 | J36: =('Operating Model - IS, BS, CF'!I5/AVERAGE('Operating Model - IS, BS, CF'!H39:I39)) -> 13.544128 | K36: =('Operating Model - IS, BS, CF'!J5/AVERAGE('Operating Model - IS, BS, CF'!I39:J39)) -> 13.544128
C37: Payable Turnover | F37: =-'Operating Model - IS, BS, CF'!E7/AVERAGE('Operating Model - IS, BS, CF'!D56:E56) -> 3.6499899 | G37: =-'Operating Model - IS, BS, CF'!F7/AVERAGE('Operating Model - IS, BS, CF'!E56:F56) -> 3.70321 | H37: =-'Operating Model - IS, BS, CF'!G7/AVERAGE('Operating Model - IS, BS, CF'!F56:G56) -> 3.9038555 | I37: =-'Operating Model - IS, BS, CF'!H7/AVERAGE('Operating Model - IS, BS, CF'!G56:H56) -> 3.8655512 | J37: =-'Operating Model - IS, BS, CF'!I7/AVERAGE('Operating Model - IS, BS, CF'!H56:I56) -> 3.8655512 | K37: =-'Operating Model - IS, BS, CF'!J7/AVERAGE('Operating Model - IS, BS, CF'!I56:J56) -> 3.8655512
C38: Inventory Turnover | F38: =-('Operating Model - IS, BS, CF'!E7/AVERAGE('Operating Model - IS, BS, CF'!D40:'Operating Model - IS, BS, CF'!E40)) -> 8.583898 | G38: =-('Operating Model - IS, BS, CF'!F7/AVERAGE('Operating Model - IS, BS, CF'!E40:'Operating Model - IS, BS, CF'!F40)) -> 8.9995718 | H38: =-('Operating Model - IS, BS, CF'!G7/AVERAGE('Operating Model - IS, BS, CF'!F40:'Operating Model - IS, BS, CF'!G40)) -> 9.6142996 | I38: =-('Operating Model - IS, BS, CF'!H7/AVERAGE('Operating Model - IS, BS, CF'!G40:'Operating Model - IS, BS, CF'!H40)) -> 9.2388862 | J38: =-('Operating Model - IS, BS, CF'!I7/AVERAGE('Operating Model - IS, BS, CF'!H40:'Operating Model - IS, BS, CF'!I40)) -> 9.2388862 | K38: =-('Operating Model - IS, BS, CF'!J7/AVERAGE('Operating Model - IS, BS, CF'!I40:'Operating Model - IS, BS, CF'!J40)) -> 9.2388862
C40: Days
C41: DSO | F41: =365/F36 -> 26.630258 | G41: =365/G36 -> 30.040576 | H41: =365/H36 -> 29.195189 | I41: =365/I36 -> 26.948947 | J41: =365/J36 -> 26.948947 | K41: =365/K36 -> 26.948947
C42: DPO | F42: =365/F37 -> 100.00028 | G42: =365/G37 -> 98.563139 | H42: =365/H37 -> 93.497314 | I42: =365/I37 -> 94.423791 | J42: =365/J37 -> 94.423791 | K42: =365/K37 -> 94.423791
C43: DIH | F43: =365/F38 -> 42.521474 | G43: =365/G38 -> 40.557485 | H43: =365/H38 -> 37.964284 | I43: =365/I38 -> 39.506927 | J43: =365/J38 -> 39.506927 | K43: =365/K38 -> 39.506927
C45: Cash Conversion Cycle | F45: =F41+F43-F42 -> -30.848544 | G45: =G41+G43-G42 -> -27.965078 | H45: =H41+H43-H42 -> -26.337841 | I45: =I41+I43-I42 -> -27.967917 | J45: =J41+J43-J42 -> -27.967917 | K45: =K41+K43-K42 -> -27.967917
C48: Per Share Data
C49: Basic EPS | G49: ='Operating Model - IS, BS, CF'!F31/Assumption!E39 -> 2.929516

Sheet D&A Schedule
B3: x | C3: D&A | D3: For the Year Ended (FYE)
D4: 2021 | E4: =D4+1 -> 2022 | F4: =E4+1 -> 2023 | G4: =F4+1 -> 2024 | H4: =G4+1 -> 2025 | I4: =H4+1 -> 2026 | J4: =I4+1 -> 2027 | K4: =J4+1 -> 2028
C5: Revenue | D5: ='Operating Model - IS, BS, CF'!D5 -> 469822 | E5: ='Operating Model - IS, BS, CF'!E5 -> 513983 | F5: ='Operating Model - IS, BS, CF'!F5 -> 574785 | G5: ='Operating Model - IS, BS, CF'!G5 -> 634582.24 | H5: ='Operating Model - IS, BS, CF'!H5 -> 703419.81 | I5: ='Operating Model - IS, BS, CF'!I5 -> 779724.66 | J5: ='Operating Model - IS, BS, CF'!J5 -> 864306.83 | K5: ='Operating Model - IS, BS, CF'!K5 -> 958064.21
C6: Capital Expenditure | D6: ='Operating Model - IS, BS, CF'!D90 -> -61053 | E6: ='Operating Model - IS, BS, CF'!E90 -> -63645 | F6: ='Operating Model - IS, BS, CF'!F90 -> -52729 | G6: =G5*G7 -> -73085.509 | H6: =H5*H7 -> -81013.604 | I6: =I5*I7 -> -89801.715 | J6: =J5*J7 -> -99543.133 | K6: =K5*K7 -> -110341.27
C7: % of Sales | D7: =D6/D5 -> -0.12994921 | E7: =E6/E5 -> -0.12382705 | F7: =F6/F5 -> -0.09173691 | G7: =AVERAGE(D7:F7) -> -0.11517106 | H7: =G7 -> -0.11517106 | I7: =H7 -> -0.11517106 | J7: =I7 -> -0.11517106 | K7: =J7 -> -0.11517106
C9: PP&E - Opening | E9: =D12 -> 160281 | F9: =E12 -> 186715 | G9: =F12 -> 204177 | H9: =G12 -> 223202.66 | I9: =H12 -> 245054.56 | J9: =I12 -> 269867.49 | K9: =J12 -> 297784.63
B10: + | C10: Capital Exp | E10: =-E6 -> 63645 | F10: =-F6 -> 52729 | G10: =-G6 -> 73085.509 | H10: =-H6 -> 81013.604 | I10: =-I6 -> 89801.715 | J10: =-J6 -> 99543.133 | K10: =-K6 -> 110341.27
B11: - | C11: Depreciation | G11: =-G14 -> -54059.846 | H11: =-H14 -> -59161.704 | I11: =-I14 -> -64988.791 | J11: =-J14 -> -71625.989 | K11: =-K14 -> -79056.745
C12: PP&E - Closing | D12: ='Operating Model - IS, BS, CF'!D45 -> 160281 | E12: ='Operating Model - IS, BS, CF'!E45 -> 186715 | F12: ='Operating Model - IS, BS, CF'!F45 -> 204177 | G12: =SUM(G9:G11) -> 223202.66 | H12: =SUM(H9:H11) -> 245054.56 | I12: =SUM(I9:I11) -> 269867.49 | J12: =SUM(J9:J11) -> 297784.63 | K12: =SUM(K9:K11) -> 329069.16
C14: D&A | D14: ='Operating Model - IS, BS, CF'!D85 -> 34433 | E14: ='Operating Model - IS, BS, CF'!E85 -> 41921 | F14: ='Operating Model - IS, BS, CF'!F85 -> 48663 | G14: =SUM(G16,Assumption!G13) -> 54059.846 | H14: =SUM(H16,Assumption!H13) -> 59161.704 | I14: =SUM(I16,Assumption!I13) -> 64988.791 | J14: =SUM(J16,Assumption!J13) -> 71625.989 | K14: =SUM(K16,Assumption!K13) -> 79056.745
C16: Depreciation | D16: =D14-Assumption!D13 -> 33921 | E16: =E14-Assumption!E13 -> 41317 | F16: =F14-Assumption!F13 -> 47957 | G16: =SUM(G9:G10)*Assumption!G16 -> 53344.846 | H16: =SUM(H9:H10)*Assumption!H16 -> 58530.704 | I16: =SUM(I9:I10)*Assumption!I16 -> 64425.791 | J16: =SUM(J9:J10)*Assumption!J16 -> 71073.989 | K16: =SUM(K9:K10)*Assumption!K16 -> 78522.745
C22: Intangible Assets - Opening Balance | E22: =D25 -> 5107 | F22: =E25 -> 6097 | G22: =F25 -> 7687 | H22: =G25 -> 6972 | I22: =H25 -> 6341 | J22: =I25 -> 5778 | K22: =J25 -> 5226
B23: + | C23: Additions | G23: =Assumption!G11 -> 0 | H23: =Assumption!H11 -> 0 | I23: =Assumption!I11 -> 0 | J23: =Assumption!J11 -> 0 | K23: =Assumption!K11 -> 0
B24: - | C24: Amortization | G24: =-Assumption!G13 -> -715 | H24: =-Assumption!H13 -> -631 | I24: =-Assumption!I13 -> -563 | J24: =-Assumption!J13 -> -552 | K24: =-Assumption!K13 -> -534
C25: Intangible Assets - Closing Balance | D25: 5107 | E25: 6097 | F25: 7687 | G25: =SUM(G22:G24) -> 6972 | H25: =SUM(H22:H24) -> 6341 | I25: =SUM(I22:I24) -> 5778 | J25: =SUM(J22:J24) -> 5226 | K25: =SUM(K22:K24) -> 4692

Sheet Working Cap Schedule
B3: x | C3: Working Cap | D3: For the Year Ended (FYE)
D4: 2021 | E4: =D4+1 -> 2022 | F4: =E4+1 -> 2023 | G4: =F4+1 -> 2024 | H4: =G4+1 -> 2025 | I4: =H4+1 -> 2026 | J4: =I4+1 -> 2027 | K4: =J4+1 -> 2028
C5: Revenue | D5: ='Operating Model - IS, BS, CF'!D5 -> 469822 | E5: ='Operating Model - IS, BS, CF'!E5 -> 513983 | F5: ='Operating Model - IS, BS, CF'!F5 -> 574785 | G5: ='Operating Model - IS, BS, CF'!G5 -> 634582.24 | H5: ='Operating Model - IS, BS, CF'!H5 -> 703419.81 | I5: ='Operating Model - IS, BS, CF'!I5 -> 779724.66 | J5: ='Operating Model - IS, BS, CF'!J5 -> 864306.83 | K5: ='Operating Model - IS, BS, CF'!K5 -> 958064.21
C6: Cost of Revenue | D6: ='Operating Model - IS, BS, CF'!D7 -> -272344 | E6: ='Operating Model - IS, BS, CF'!E7 -> -288831 | F6: ='Operating Model - IS, BS, CF'!F7 -> -304739 | G6: ='Operating Model - IS, BS, CF'!G7 -> -353631.65 | H6: ='Operating Model - IS, BS, CF'!H7 -> -391992.54 | I6: ='Operating Model - IS, BS, CF'!I7 -> -434514.71 | J6: ='Operating Model - IS, BS, CF'!J7 -> -481649.55 | K6: ='Operating Model - IS, BS, CF'!K7 -> -533897.43
C8: Non Cash Current Assets
C9: Account Receivable | D9: ='Operating Model - IS, BS, CF'!D39 -> 32640 | E9: ='Operating Model - IS, BS, CF'!E39 -> 42360 | F9: ='Operating Model - IS, BS, CF'!F39 -> 52253 | G9: =Assumption!G20*G5/G36 -> 49263.432 | H9: =Assumption!H20*H5/H36 -> 54607.38 | I9: =Assumption!I20*I5/I36 -> 60531.023 | J9: =Assumption!J20*J5/J36 -> 67097.245 | K9: =Assumption!K20*K5/K36 -> 74375.751
C10: Inventory | D10: ='Operating Model - IS, BS, CF'!D40 -> 32891 | E10: ='Operating Model - IS, BS, CF'!E40 -> 34405 | F10: ='Operating Model - IS, BS, CF'!F40 -> 33318 | G10: =-Assumption!G21*G6/G36 -> 40245.685 | H10: =-Assumption!H21*H6/H36 -> 44611.415 | I10: =-Assumption!I21*I6/I36 -> 49450.726 | J10: =-Assumption!J21*J6/J36 -> 54814.991 | K10: =-Assumption!K21*K6/K36 -> 60761.155
C11: Prepaid Exp | D11: 0 | E11: 0 | F11: 0 | G11: 0 | H11: 0 | I11: 0 | J11: 0 | K11: 0
C12: Total | D12: =SUM(D9:D11) -> 65531 | E12: =SUM(E9:E11) -> 76765 | F12: =SUM(F9:F11) -> 85571 | G12: =SUM(G9:G11) -> 89509.116 | H12: =SUM(H9:H11) -> 99218.794 | I12: =SUM(I9:I11) -> 109981.75 | J12: =SUM(J9:J11) -> 121912.24 | K12: =SUM(K9:K11) -> 135136.91
C14: Non Debt Current Liabilites
C15: Account Payable | D15: ='Operating Model - IS, BS, CF'!D56 -> 78664 | E15: ='Operating Model - IS, BS, CF'!E56 -> 79600 | F15: ='Operating Model - IS, BS, CF'!F56 -> 84981 | G15: =-Assumption!G23*G6/G36 -> 96189.464 | H15: =-Assumption!H23*H6/H36 -> 106623.81 | I15: =-Assumption!I23*I6/I36 -> 118190.03 | J15: =-Assumption!J23*J6/J36 -> 131010.93 | K15: =-Assumption!K23*K6/K36 -> 145222.6 | M15: =SUM(H9:H10)-H15 -> -7405.0118
C16: Accrued expenses and other | D16: ='Operating Model - IS, BS, CF'!D58 -> 51775 | E16: ='Operating Model - IS, BS, CF'!E58 -> 62566 | F16: ='Operating Model - IS, BS, CF'!F58 -> 64709 | G16: ='Operating Model - IS, BS, CF'!G58 -> 64709 | H16: ='Operating Model - IS, BS, CF'!H58 -> 64709 | I16: ='Operating Model - IS, BS, CF'!I58 -> 64709 | J16: ='Operating Model - IS, BS, CF'!J58 -> 64709 | K16: ='Operating Model - IS, BS, CF'!K58 -> 64709
C17: Unearned revenue | D17: ='Operating Model - IS, BS, CF'!D59 -> 11827 | E17: ='Operating Model - IS, BS, CF'!E59 -> 13227 | F17: ='Operating Model - IS, BS, CF'!F59 -> 15227 | G17: =G5*G18 -> 16372.079 | H17: =H5*H18 -> 18294.949 | I17: =I5*I18 -> 20350.813 | J17: =J5*J18 -> 22445.573 | K17: =K5*K18 -> 24934.588
C18: % of sales | D18: =D17/D5 -> 0.025173364 | E18: =E17/E5 -> 0.025734314 | F18: =F17/F5 -> 0.026491645 | G18: =AVERAGE(D18:F18) -> 0.025799774 | H18: =AVERAGE(E18:G18) -> 0.026008578 | I18: =AVERAGE(F18:H18) -> 0.026099999 | J18: =AVERAGE(G18:I18) -> 0.02596945 | K18: =AVERAGE(H18:J18) -> 0.026026009
C19: Total | D19: =SUM(D15:D17) -> 142266 | E19: =SUM(E15:E17) -> 155393 | F19: =SUM(F15:F17) -> 164917 | G19: =SUM(G15:G17) -> 177270.54 | H19: =SUM(H15:H17) -> 189627.75 | I19: =SUM(I15:I17) -> 203249.85 | J19: =SUM(J15:J17) -> 218165.5 | K19: =SUM(K15:K17) -> 234866.19
C22: Net Working Cap | D22: =D12-D19 -> -76735 | E22: =E12-E19 -> -78628 | F22: =F12-F19 -> -79346 | G22: =G12-G19 -> -87761.426 | H22: =H12-H19 -> -90408.96 | I22: =I12-I19 -> -93268.098 | J22: =J12-J19 -> -96253.268 | K22: =K12-K19 -> -99729.282
C23: Changes in working cap | E23: =E22-D22 -> -1893 | F23: =F22-E22 -> -718 | G23: =G22-F22 -> -8415.4265 | H23: =H22-G22 -> -2647.534 | I23: =I22-H22 -> -2859.1372 | J23: =J22-I22 -> -2985.1704 | K23: =K22-J22 -> -3476.0135
C25: Receivable Turnover | E25: =E5/AVERAGE(D9:E9) -> 13.706213 | F25: =F5/AVERAGE(E9:F9) -> 12.150233 | G25: =G5/AVERAGE(F9:G9) -> 12.50206 | H25: =H5/AVERAGE(G9:H9) -> 13.544128 | I25: =I5/AVERAGE(H9:I9) -> 13.544128 | J25: =J5/AVERAGE(I9:J9) -> 13.544128 | K25: =K5/AVERAGE(J9:K9) -> 13.544128
C26: Inventory Turnover | E26: =-E6/AVERAGE(D10:E10) -> 8.583898 | F26: =-F6/AVERAGE(E10:F10) -> 8.9995718 | G26: =-G6/AVERAGE(F10:G10) -> 9.6142996 | H26: =-H6/AVERAGE(G10:H10) -> 9.2388862 | I26: =-I6/AVERAGE(H10:I10) -> 9.2388862 | J26: =-J6/AVERAGE(I10:J10) -> 9.2388862 | K26: =-K6/AVERAGE(J10:K10) -> 9.2388862
C28: Payable Turnover | E28: =-E6/AVERAGE(D15:E15) -> 3.6499899 | F28: =-F6/AVERAGE(E15:F15) -> 3.70321 | G28: =-G6/AVERAGE(F15:G15) -> 3.9038555 | H28: =-H6/AVERAGE(G15:H15) -> 3.8655512 | I28: =-I6/AVERAGE(H15:I15) -> 3.8655512 | J28: =-J6/AVERAGE(I15:J15) -> 3.8655512 | K28: =-K6/AVERAGE(J15:K15) -> 3.8655512
C36: No of Days | D36: 365 | E36: 365 | F36: 365 | G36: 365 | H36: 365 | I36: 365 | J36: 365 | K36: 365

Sheet Debt and Interest Schedule 
B3: x | C3: Debt Schedule | D3: For the Year Ended (FYE) | T3: Maturity | U3: Stated Interest Rate | V3: December 31, 2023 | X3: Interest
D4: 2021 | E4: =D4+1 -> 2022 | F4: =E4+1 -> 2023 | G4: =F4+1 -> 2024 | H4: =G4+1 -> 2025 | I4: =H4+1 -> 2026 | J4: =I4+1 -> 2027 | K4: =J4+1 -> 2028 | S4: 2014 Notes issuance of $6.0 billion | T4: 2044 | U4: 0.038 | V4: 4000 | X4: =U4*V4 -> 152
C5: LT Debt - opening | E5: =D8 -> 48744 | F5: =E8 -> 67150 | G5: =F8 -> 58314 | H5: =G8 -> 58314 | I5: =H8 -> 58314 | J5: =I8 -> 58314 | K5: =J8 -> 58314 | S5: 2017 Notes issuance of $17.0 billion | T5: 2057 | U5: 0.028 | V5: 15000 | X5: =U5*V5 -> 420
C6: Issuance | G6: =Assumption!G27 -> 0 | H6: =Assumption!H27 -> 0 | I6: =Assumption!I27 -> 0 | J6: =Assumption!J27 -> 0 | K6: =Assumption!K27 -> 0 | S6: 2020 Notes issuance of $10.0 billion | T6: 2060 | U6: 0.008 | V6: 9000 | X6: =U6*V6 -> 72
C7: Repayment | G7: =Assumption!G28 -> -8500 | H7: =Assumption!H28 -> -5286 | I7: =Assumption!I28 -> -3146 | J7: =Assumption!J28 -> -8750 | K7: =Assumption!K28 -> -2250 | S7: 2021 Notes issuance of $18.5 billion | T7: 2061 | U7: 0.0045 | V7: 17500 | X7: =U7*V7 -> 78.75
C8: LT Debt - closing | D8: ='Operating Model - IS, BS, CF'!D64 -> 48744 | E8: ='Operating Model - IS, BS, CF'!E64 -> 67150 | F8: ='Operating Model - IS, BS, CF'!F64 -> 58314 | G8: =SUM(G5:G5) -> 58314 | H8: =SUM(H5:H5) -> 58314 | I8: =SUM(I5:I5) -> 58314 | J8: =SUM(J5:J5) -> 58314 | K8: =SUM(K5:K5) -> 58314 | S8: April 2022 Notes issuance of $12.8 billion | T8: 2062 | U8: 0.0273 | V8: 12750 | X8: =U8*V8 -> 348.075
S9: December 2022 Notes issuance of $8.3 billion | T9: 2032 | U9: 0.0455 | V9: 8250 | X9: =U9*V9 -> 375.375
V10: 682
C11: Interest Exp | G11: =-SUM(G5:G5)*$U$11 -> -1255.3021 | H11: =-SUM(H5:H5)*$U$11 -> -1255.3021 | I11: =-SUM(I5:I5)*$U$11 -> -1255.3021 | J11: =-SUM(J5:J5)*$U$11 -> -1255.3021 | K11: =-SUM(K5:K5)*$U$11 -> -1255.3021 | U11: =X11/V11 -> 0.021526599 | V11: =SUM(V4:V10) -> 67182 | X11: =SUM(X4:X9) -> 1446.2
C12: Interest Income | G12: ='Operating Model - IS, BS, CF'!G106*Assumption!$G$30 -> 446.81665 | H12: ='Operating Model - IS, BS, CF'!H106*Assumption!$G$30 -> 519.80022 | I12: ='Operating Model - IS, BS, CF'!I106*Assumption!$G$30 -> 611.97731 | J12: ='Operating Model - IS, BS, CF'!J106*Assumption!$G$30 -> 685.72467 | K12: ='Operating Model - IS, BS, CF'!K106*Assumption!$G$30 -> 804.95296
C14: Net Interest (Exp) / Income | G14: =SUM(G11:G12) -> -808.48547 | H14: =SUM(H11:H12) -> -735.50189 | I14: =SUM(I11:I12) -> -643.32481 | J14: =SUM(J11:J12) -> -569.57744 | K14: =SUM(K11:K12) -> -450.34915
C16: Total Cash Flow After Mandatory Payments
C17: Cash and Cash Equivalent - opening | G17: ='Operating Model - IS, BS, CF'!G104 -> 73387 | H17: ='Operating Model - IS, BS, CF'!H104 -> 89363.33 | I17: ='Operating Model - IS, BS, CF'!I104 -> 103960.04 | J17: ='Operating Model - IS, BS, CF'!J104 -> 122395.46 | K17: ='Operating Model - IS, BS, CF'!K104 -> 137144.93
C18: Cash Flow from Operations (CFO) | G18: ='Operating Model - IS, BS, CF'!G88 -> 97561.839 | H18: ='Operating Model - IS, BS, CF'!H88 -> 100896.32 | I18: ='Operating Model - IS, BS, CF'!I88 -> 111383.13 | J18: ='Operating Model - IS, BS, CF'!J88 -> 123042.61 | K18: ='Operating Model - IS, BS, CF'!K88 -> 136436.93
C19: Cash Flow from Investing (CFI) | G19: ='Operating Model - IS, BS, CF'!G92 -> -73085.509 | H19: ='Operating Model - IS, BS, CF'!H92 -> -81013.604 | I19: ='Operating Model - IS, BS, CF'!I92 -> -89801.715 | J19: ='Operating Model - IS, BS, CF'!J92 -> -99543.133 | K19: ='Operating Model - IS, BS, CF'!K92 -> -110341.27
C20: Equity Issuance / Equity Raise | G20: ='Operating Model - IS, BS, CF'!G94 -> 0 | H20: ='Operating Model - IS, BS, CF'!H94 -> 0 | I20: ='Operating Model - IS, BS, CF'!I94 -> 0 | J20: ='Operating Model - IS, BS, CF'!J94 -> 0 | K20: ='Operating Model - IS, BS, CF'!K94 -> 0
C21: Equity Repurchase | G21: ='Operating Model - IS, BS, CF'!G95 -> 0 | H21: ='Operating Model - IS, BS, CF'!H95 -> 0 | I21: ='Operating Model - IS, BS, CF'!I95 -> 0 | J21: ='Operating Model - IS, BS, CF'!J95 -> 0 | K21: ='Operating Model - IS, BS, CF'!K95 -> 0
C22: Dividend Paid | G22: ='Operating Model - IS, BS, CF'!G96 -> 0 | H22: ='Operating Model - IS, BS, CF'!H96 -> 0 | I22: ='Operating Model - IS, BS, CF'!I96 -> 0 | J22: ='Operating Model - IS, BS, CF'!J96 -> 0 | K22: ='Operating Model - IS, BS, CF'!K96 -> 0
C23: Debt Issuance | G23: ='Operating Model - IS, BS, CF'!G97 -> 0 | H23: ='Operating Model - IS, BS, CF'!H97 -> 0 | I23: ='Operating Model - IS, BS, CF'!I97 -> 0 | J23: ='Operating Model - IS, BS, CF'!J97 -> 0 | K23: ='Operating Model - IS, BS, CF'!K97 -> 0
C24: Debt Repayment | G24: ='Operating Model - IS, BS, CF'!G98 -> -8500 | H24: ='Operating Model - IS, BS, CF'!H98 -> -5286 | I24: ='Operating Model - IS, BS, CF'!I98 -> -3146 | J24: ='Operating Model - IS, BS, CF'!J98 -> -8750 | K24: ='Operating Model - IS, BS, CF'!K98 -> -2250
C25: Total Cash after mandatory Payments | G25: =SUM(G17:G24) -> 89363.33 | H25: =SUM(H17:H24) -> 103960.04 | I25: =SUM(I17:I24) -> 122395.46 | J25: =SUM(J17:J24) -> 137144.93 | K25: =SUM(K17:K24) -> 160990.59
C27: Short Term Debt - opening | E27: =D29 -> 0 | F27: =E29 -> 0 | G27: =F29 -> 0 | H27: =G29 -> 0 | I27: =H29 -> 0 | J27: =I29 -> 0 | K27: =J29 -> 0
C28: Issuance / (repayment) | G28: =MIN(G27,G25) -> 0 | H28: =MIN(H27,H25) -> 0 | I28: =MIN(I27,I25) -> 0 | J28: =MIN(J27,J25) -> 0 | K28: =MIN(K27,K25) -> 0
C29: Short Term Debt - closing | D29: ='Operating Model - IS, BS, CF'!D57 -> 0 | E29: ='Operating Model - IS, BS, CF'!E57 -> 0 | F29: ='Operating Model - IS, BS, CF'!F57 -> 0 | G29: =SUM(G27,G28) -> 0 | H29: =SUM(H27,H28) -> 0 | I29: =SUM(I27,I28) -> 0 | J29: =SUM(J27,J28) -> 0 | K29: =SUM(K27,K28) -> 0

Sheet Equity Schedule
B3: x | C3: Equity Schedule | D3: For the Year Ended (FYE)
D4: 2021 | E4: =D4+1 -> 2022 | F4: =E4+1 -> 2023 | G4: =F4+1 -> 2024 | H4: =G4+1 -> 2025 | I4: =H4+1 -> 2026 | J4: =I4+1 -> 2027 | K4: =J4+1 -> 2028
C5: Equity Cap - Opening | E5: =D8 -> 52330 | F5: =E8 -> 62850 | G5: =F8 -> 88257 | H5: =G8 -> 88257 | I5: =H8 -> 88257 | J5: =I8 -> 88257 | K5: =J8 -> 88257
B6: + | C6: Issuance | G6: =Assumption!G34 -> 0 | H6: =Assumption!H34 -> 0 | I6: =Assumption!I34 -> 0 | J6: =Assumption!J34 -> 0 | K6: =Assumption!K34 -> 0
B7: - | C7: Repurchase | G7: =Assumption!G35 -> 0 | H7: =Assumption!H35 -> 0 | I7: =Assumption!I35 -> 0 | J7: =Assumption!J35 -> 0 | K7: =Assumption!K35 -> 0
C8: Equity Cap - Closing | D8: ='Operating Model - IS, BS, CF'!D73 -> 52330 | E8: ='Operating Model - IS, BS, CF'!E73 -> 62850 | F8: ='Operating Model - IS, BS, CF'!F73 -> 88257 | G8: =SUM(G5:G7) -> 88257 | H8: =SUM(H5:H7) -> 88257 | I8: =SUM(I5:I7) -> 88257 | J8: =SUM(J5:J7) -> 88257 | K8: =SUM(K5:K7) -> 88257
C11: Retained Earning opening | E11: =D14 -> 85915 | F11: =E14 -> 83193 | G11: =F14 -> 113618 | H11: =G14 -> 148704.57 | I11: =H14 -> 187791.65 | J11: =I14 -> 231326.85 | K11: =J14 -> 279758.3
C12: Net income | G12: ='Operating Model - IS, BS, CF'!G31 -> 35086.567 | H12: ='Operating Model - IS, BS, CF'!H31 -> 39087.081 | I12: ='Operating Model - IS, BS, CF'!I31 -> 43535.203 | J12: ='Operating Model - IS, BS, CF'!J31 -> 48431.446 | K12: ='Operating Model - IS, BS, CF'!K31 -> 53904.17
C13: Dividend
C14: Retained Earning closing | D14: ='Operating Model - IS, BS, CF'!D74 -> 85915 | E14: ='Operating Model - IS, BS, CF'!E74 -> 83193 | F14: ='Operating Model - IS, BS, CF'!F74 -> 113618 | G14: =SUM(G11:G13) -> 148704.57 | H14: =SUM(H11:H13) -> 187791.65 | I14: =SUM(I11:I13) -> 231326.85 | J14: =SUM(J11:J13) -> 279758.3 | K14: =SUM(K11:K13) -> 333662.47
C17: Dividend per share | E17: N/A

Sheet DCF
B3: x | C3: Equity Schedule | D3: For the Year Ended (FYE)
D4: 2023 | G4: 2024 | H4: 2025 | I4: 2026 | J4: 2027 | K4: 2028 | S4: 2029 onwards | U4: WAAC | V4: =W10*V15*(1-V21)+W9*V12 -> 0.10147656
C6: EBIT*(1+Tax) | G6: ='Operating Model - IS, BS, CF'!G24*(1-Assumption!G8) -> 23546.462 | H6: ='Operating Model - IS, BS, CF'!H24*(1-Assumption!H8) -> 26100.711 | I6: ='Operating Model - IS, BS, CF'!I24*(1-Assumption!I8) -> 28932.037 | J6: ='Operating Model - IS, BS, CF'!J24*(1-Assumption!J8) -> 32070.497 | K6: ='Operating Model - IS, BS, CF'!K24*(1-Assumption!K8) -> 35549.407 | U6: Equity | W6: =227.61*Assumption!E39 -> 2364271.9
B7: + | C7: D&A | G7: ='Operating Model - IS, BS, CF'!G85 -> 54059.846 | H7: ='Operating Model - IS, BS, CF'!H85 -> 59161.704 | I7: ='Operating Model - IS, BS, CF'!I85 -> 64988.791 | J7: ='Operating Model - IS, BS, CF'!J85 -> 71625.989 | K7: ='Operating Model - IS, BS, CF'!K85 -> 79056.745 | U7: Debt | W7: ='Operating Model - IS, BS, CF'!F57+'Operating Model - IS, BS, CF'!F64 -> 58314
B8: - | C8: Capex | G8: ='Operating Model - IS, BS, CF'!G90 -> -73085.509 | H8: ='Operating Model - IS, BS, CF'!H90 -> -81013.604 | I8: ='Operating Model - IS, BS, CF'!I90 -> -89801.715 | J8: ='Operating Model - IS, BS, CF'!J90 -> -99543.133 | K8: ='Operating Model - IS, BS, CF'!K90 -> -110341.27
C9: Changes in working capital | G9: =-'Working Cap Schedule'!G23 -> 8415.4265 | H9: =-'Working Cap Schedule'!H23 -> 2647.534 | I9: =-'Working Cap Schedule'!I23 -> 2859.1372 | J9: =-'Working Cap Schedule'!J23 -> 2985.1704 | K9: =-'Working Cap Schedule'!K23 -> 3476.0135 | U9: Weight of Equity | W9: =W6/SUM(W6:W7) -> 0.97592903
C10: Free cash flow to firm(FCFF) | G10: =SUM(G6:G9) -> 12936.225 | H10: =SUM(H6:H9) -> 6896.3449 | I10: =SUM(I6:I9) -> 6978.2509 | J10: =SUM(J6:J9) -> 7138.5236 | K10: =SUM(K6:K9) -> 7740.8953 | U10: Weight of debt | W10: =W7/SUM(W6:W7) -> 0.024070974
H11: =H10/G10-1 -> -0.46689665 | I11: =I10/H10-1 -> 0.011876724 | J11: =J10/I10-1 -> 0.022967462 | K11: =K10/J10-1 -> 0.084383233
D12: PGM | F12: EMM | U12: Cost of equity | V12: =V16+V17*V18 -> 0.10356
C13: Exit multiple 2028 | F13: 13
C15: Terminal value 2028 | D15: =K10*(1+D16)/(V4-D16) -> 157895.94 | F15: =F13*'Operating Model - IS, BS, CF'!K22 -> 1612727.9 | U15: Cost of debt | V15: =Assumption!G31 -> 0.021526599
C16: Growth rate | D16: 0.05 | U16: risk free retutrn | V16: 0.045
U17: beta | V17: 1.22
C18: Present value of cash flow | D18: =NPV($V$4,G10:K10) -> 32274.408 | F18: =D18 -> 32274.408 | U18: market risk premium | V18: 0.048
C19: Present value of Terminal value | D19: =D15/(1+V4)^5 -> 97385.582 | F19: =F15/(1+V4)^5 -> 994683.25
C20: EV | D20: =SUM(D18:D19) -> 129659.99 | F20: =SUM(F18:F19) -> 1026957.7
B21: - | C21: Debt | D21: =-W7 -> -58314 | F21: =D21 -> -58314 | U21: Tax rate | V21: 0.21
B22: - | C22: minority | D22: 0 | F22: =D22 -> 0
B23: - | C23: leases | D23: =-'Operating Model - IS, BS, CF'!F63 -> -77297 | F23: =D23 -> -77297
B24: - | C24: prefered | D24: 0 | F24: =D24 -> 0
B25: + | C25: cash | D25: ='Operating Model - IS, BS, CF'!F37+'Operating Model - IS, BS, CF'!F38 -> 86780 | F25: =D25 -> 86780
C26: Equity value | D26: =SUM(D20:D25) -> 80828.99 | F26: =SUM(F20:F25) -> 978126.66
C28: Share outstanding | D28: =Assumption!E39 -> 10387.381 | F28: =D28 -> 10387.381
C30: Intrinsc price per share | D30: =D26/D28 -> 7.7814598 | F30: =F26/F28 -> 94.164894
H35: WACC
F36: =D30 -> 7.7814598 | G36: 0.085 | H36: 0.09 | I36: 0.1 | J36: 0.11
F37: 0.05 | G37: 13.396417 | H37: 11.204301 | I37: 8.1339026 | J37: 6.0854042
E38: Growth rate | F38: 0.06 | G38: 19.541929 | H38: 15.603746 | I38: 10.678883 | J38: 7.7217382
F39: 0.07 | G39: 33.881459 | H39: 24.402636 | I39: 14.920516 | J39: 10.176239
F40: 0.08 | G40: 105.57911 | H40: 50.799305 | I40: 23.403783 | J40: 14.267074
H43: WACC
F44: =F30 -> 94.164894 | G44: 0.085 | H44: 0.09 | I44: 0.1 | J44: 0.11
F45: 11 | G45: 85.896901 | H45: 83.873401 | I45: 79.988674 | J45: 76.309154
E46: Exit Multiple | F46: 12 | G46: 93.839506 | H46: 91.6355 | I46: 87.404307 | J46: 83.396714
F47: 13 | G47: 101.78211 | H47: 99.397599 | I47: 94.819941 | J47: 90.484275
F48: 14 | G48: 109.72472 | H48: 107.1597 | I48: 102.23557 | J48: 97.571835
G51: Min | H51: difference | I51: Max
F52: PGM | G52: =MIN(G37:J40) -> 6.0854042 | H52: =I52-G52 -> 99.493702 | I52: =MAX(G37:J40) -> 105.57911
F53: EMM | G53: =MIN(G45:J48) -> 76.309154 | H53: =I53-G53 -> 33.415564 | I53: =MAX(G45:J48) -> 109.72472
F54: 52 weeks H/L | G54: 81.43 | H54: =I54-G54 -> 151.57 | I54: 233
